Workbook

Sheet Importrange
A1: =IFERROR(__xludf.DUMMYFUNCTION("importrange(""https://docs.google.com/spreadsheets/d/1eo-EGIGL2ZuDJLGtOqMpijjPglTyJJR_lkYk4Gthvhs/edit?gid=684256595#gid=684256595"",""ELEVES COMPLETE!A:ZZ"")"),"Nom complet") -> Nom complet | B1: =IFERROR(__xludf.DUMMYFUNCTION("""COMPUTED_VALUE"""),"Nom") -> Nom | C1: =IFERROR(__xludf.DUMMYFUNCTION("""COMPUTED_VALUE"""),"Prénom") -> Prénom | D1: =IFERROR(__xludf.DUMMYFUNCTION("""COMPUTED_VALUE"""),"Code identifiant") -> Code identifiant | E1: =IFERROR(__xludf.DUMMYFUNCTION("""COMPUTED_VALUE"""),"Date de naissance") -> Date de naissance | F1: =IFERROR(__xludf.DUMMYFUNCTION("""COMPUTED_VALUE"""),"Classe") -> Classe | G1: =IFERROR(__xludf.DUMMYFUNCTION("""COMPUTED_VALUE"""),"Niveau") -> Niveau | H1: =IFERROR(__xludf.DUMMYFUNCTION("""COMPUTED_VALUE"""),"Branche scolaire") -> Branche scolaire | I1: =IFERROR(__xludf.DUMMYFUNCTION("""COMPUTED_VALUE"""),"LVA") -> LVA | J1: =IFERROR(__xludf.DUMMYFUNCTION("""COMPUTED_VALUE"""),"LVB") -> LVB | K1: =IFERROR(__xludf.DUMMYFUNCTION("""COMPUTED_VALUE"""),"Enseignements optionnels") -> Enseignements optionnels | L1: =IFERROR(__xludf.DUMMYFUNCTION("""COMPUTED_VALUE"""),"Option Facultative") -> Option Facultative | M1: =IFERROR(__xludf.DUMMYFUNCTION("""COMPUTED_VALUE"""),"Code Enseignements de spécialité") -> Code Enseignements de spécialité | N1: =IFERROR(__xludf.DUMMYFUNCTION("""COMPUTED_VALUE"""),"Sexe") -> Sexe | O1: =IFERROR(__xludf.DUMMYFUNCTION("""COMPUTED_VALUE"""),"Commune de naissance") -> Commune de naissance | P1: =IFERROR(__xludf.DUMMYFUNCTION("""COMPUTED_VALUE"""),"Nationalité 1") -> Nationalité 1 | Q1: =IFERROR(__xludf.DUMMYFUNCTION("""COMPUTED_VALUE"""),"Nationalité 2") -> Nationalité 2 | R1: =IFERROR(__xludf.DUMMYFUNCTION("""COMPUTED_VALUE"""),"Adresse e-mail") -> Adresse e-mail | S1: =IFERROR(__xludf.DUMMYFUNCTION("""COMPUTED_VALUE"""),"Téléphone mobile") -> Téléphone mobile | T1: =IFERROR(__xludf.DUMMYFUNCTION("""COMPUTED_VALUE"""),"Nom complet R1") -> Nom complet R1 | U1: =IFERROR(__xludf.DUMMYFUNCTION("""COMPUTED_VALUE"""),"Nom complet R2") -> Nom complet R2 | V1: =IFERROR(__xludf.DUMMYFUNCTION("""COMPUTED_VALUE"""),"Adresse e-mail R1") -> Adresse e-mail R1 | W1: =IFERROR(__xludf.DUMMYFUNCTION("""COMPUTED_VALUE"""),"Adresse e-mail R2") -> Adresse e-mail R2 | X1: =IFERROR(__xludf.DUMMYFUNCTION("""COMPUTED_VALUE"""),"Téléphone mobile R1") -> Téléphone mobile R1 | Y1: =IFERROR(__xludf.DUMMYFUNCTION("""COMPUTED_VALUE"""),"Téléphone mobile R2") -> Téléphone mobile R2 | Z1: =IFERROR(__xludf.DUMMYFUNCTION("""COMPUTED_VALUE"""),"Téléphone Whatsapp R1") -> Téléphone Whatsapp R1 | AA1: =IFERROR(__xludf.DUMMYFUNCTION("""COMPUTED_VALUE"""),"Téléphone Whatsapp R2") -> Téléphone Whatsapp R2 | AB1: =IFERROR(__xludf.DUMMYFUNCTION("""COMPUTED_VALUE"""),"Date de naissance R1") -> Date de naissance R1 | AC1: =IFERROR(__xludf.DUMMYFUNCTION("""COMPUTED_VALUE"""),"Date de naissance R2") -> Date de naissance R2 | AD1: =IFERROR(__xludf.DUMMYFUNCTION("""COMPUTED_VALUE"""),"Relation avec l'enfant R1") -> Relation avec l'enfant R1 | AE1: =IFERROR(__xludf.DUMMYFUNCTION("""COMPUTED_VALUE"""),"Relation avec l'enfant R2") -> Relation avec l'enfant R2 | AF1: =IFERROR(__xludf.DUMMYFUNCTION("""COMPUTED_VALUE"""),"Nationalité 1 R1") -> Nationalité 1 R1 | AG1: =IFERROR(__xludf.DUMMYFUNCTION("""COMPUTED_VALUE"""),"Nationalité 1 R2") -> Nationalité 1 R2 | AH1: =IFERROR(__xludf.DUMMYFUNCTION("""COMPUTED_VALUE"""),"Nationalité 2 R1") -> Nationalité 2 R1 | AI1: =IFERROR(__xludf.DUMMYFUNCTION("""COMPUTED_VALUE"""),"Nationalité 2 R2") -> Nationalité 2 R2 | AJ1: =IFERROR(__xludf.DUMMYFUNCTION("""COMPUTED_VALUE"""),"Code compte") -> Code compte | AK1: =IFERROR(__xludf.DUMMYFUNCTION("""COMPUTED_VALUE"""),"Situation familiale R1") -> Situation familiale R1 | AL1: =IFERROR(__xludf.DUMMYFUNCTION("""COMPUTED_VALUE"""),"Situation familiale R2") -> Situation familiale R2 | AM1: =IFERROR(__xludf.DUMMYFUNCTION("""COMPUTED_VALUE"""),"Code compte") -> Code compte
A2: =IFERROR(__xludf.DUMMYFUNCTION("""COMPUTED_VALUE"""),"ABOUDOU AMOUSSA Inès") -> ABOUDOU AMOUSSA Inès | B2: =IFERROR(__xludf.DUMMYFUNCTION("""COMPUTED_VALUE"""),"ABOUDOU AMOUSSA") -> ABOUDOU AMOUSSA | C2: =IFERROR(__xludf.DUMMYFUNCTION("""COMPUTED_VALUE"""),"Inès") -> Inès | D2: =IFERROR(__xludf.DUMMYFUNCTION("""COMPUTED_VALUE"""),"1112E1") -> 1112E1 | E2: =IFERROR(__xludf.DUMMYFUNCTION("""COMPUTED_VALUE"""),39707) -> 39707 | F2: =IFERROR(__xludf.DUMMYFUNCTION("""COMPUTED_VALUE"""),"TERMINALE2") -> TERMINALE2 | G2: =IFERROR(__xludf.DUMMYFUNCTION("""COMPUTED_VALUE"""),"Terminale") -> Terminale | H2: =IFERROR(__xludf.DUMMYFUNCTION("""COMPUTED_VALUE"""),"Lycée Français Jacques Prévert de Saly » Lycée » Terminale » Générale") -> Lycée Français Jacques Prévert de Saly » Lycée » Terminale » Générale | I2: =IFERROR(__xludf.DUMMYFUNCTION("""COMPUTED_VALUE"""),"LVA Anglais") -> LVA Anglais | J2: =IFERROR(__xludf.DUMMYFUNCTION("""COMPUTED_VALUE"""),"LVB Espagnol") -> LVB Espagnol | M2: =IFERROR(__xludf.DUMMYFUNCTION("""COMPUTED_VALUE"""),"SPE HGGSP, SPE SES") -> SPE HGGSP, SPE SES | N2: =IFERROR(__xludf.DUMMYFUNCTION("""COMPUTED_VALUE"""),"Fille") -> Fille | P2: =IFERROR(__xludf.DUMMYFUNCTION("""COMPUTED_VALUE"""),"FRANCE") -> FRANCE | R2: =IFERROR(__xludf.DUMMYFUNCTION("""COMPUTED_VALUE"""),"ines.aboudouamoussa@lfjpsaly.org") -> ines.aboudouamoussa@lfjpsaly.org | T2: =IFERROR(__xludf.DUMMYFUNCTION("""COMPUTED_VALUE"""),"ABOUDOU AMOUSSA Hakim Ichola") -> ABOUDOU AMOUSSA Hakim Ichola | U2: =IFERROR(__xludf.DUMMYFUNCTION("""COMPUTED_VALUE"""),"ABOUDOU AMOUSSA Mame Sellé") -> ABOUDOU AMOUSSA Mame Sellé | V2: =IFERROR(__xludf.DUMMYFUNCTION("""COMPUTED_VALUE"""),"hiaboudou@yahoo.fr") -> hiaboudou@yahoo.fr | W2: =IFERROR(__xludf.DUMMYFUNCTION("""COMPUTED_VALUE"""),"msmbodj@yahoo.fr") -> msmbodj@yahoo.fr | X2: =IFERROR(__xludf.DUMMYFUNCTION("""COMPUTED_VALUE"""),"+221 78 120 62 11") -> +221 78 120 62 11 | Y2: =IFERROR(__xludf.DUMMYFUNCTION("""COMPUTED_VALUE"""),"+221 77 662 25 23") -> +221 77 662 25 23 | Z2: =IFERROR(__xludf.DUMMYFUNCTION("""COMPUTED_VALUE"""),"+33 7 78 15 64 72") -> +33 7 78 15 64 72 | AA2: =IFERROR(__xludf.DUMMYFUNCTION("""COMPUTED_VALUE"""),"+33 7 50 30 20 32") -> +33 7 50 30 20 32 | AB2: =IFERROR(__xludf.DUMMYFUNCTION("""COMPUTED_VALUE"""),25938) -> 25938 | AC2: =IFERROR(__xludf.DUMMYFUNCTION("""COMPUTED_VALUE"""),31470) -> 31470 | AD2: =IFERROR(__xludf.DUMMYFUNCTION("""COMPUTED_VALUE"""),"PERE") -> PERE | AE2: =IFERROR(__xludf.DUMMYFUNCTION("""COMPUTED_VALUE"""),"MERE") -> MERE | AF2: =IFERROR(__xludf.DUMMYFUNCTION("""COMPUTED_VALUE"""),"FRANCE") -> FRANCE | AG2: =IFERROR(__xludf.DUMMYFUNCTION("""COMPUTED_VALUE"""),"FRANCE") -> FRANCE | AI2: =IFERROR(__xludf.DUMMYFUNCTION("""COMPUTED_VALUE"""),"SENEGAL") -> SENEGAL | AJ2: =IFERROR(__xludf.DUMMYFUNCTION("""COMPUTED_VALUE"""),"F1112") -> F1112 | AK2: =IFERROR(__xludf.DUMMYFUNCTION("""COMPUTED_VALUE"""),"Marié(e)") -> Marié(e) | AL2: =IFERROR(__xludf.DUMMYFUNCTION("""COMPUTED_VALUE"""),"Marié(e)") -> Marié(e) | AM2: =IFERROR(__xludf.DUMMYFUNCTION("""COMPUTED_VALUE"""),"F1112") -> F1112
A3: =IFERROR(__xludf.DUMMYFUNCTION("""COMPUTED_VALUE"""),"ABOUDOU-SARR Eiden") -> ABOUDOU-SARR Eiden | B3: =IFERROR(__xludf.DUMMYFUNCTION("""COMPUTED_VALUE"""),"ABOUDOU-SARR") -> ABOUDOU-SARR | C3: =IFERROR(__xludf.DUMMYFUNCTION("""COMPUTED_VALUE"""),"Eiden") -> Eiden | D3: =IFERROR(__xludf.DUMMYFUNCTION("""COMPUTED_VALUE"""),"1626E1") -> 1626E1 | E3: =IFERROR(__xludf.DUMMYFUNCTION("""COMPUTED_VALUE"""),41270) -> 41270 | F3: =IFERROR(__xludf.DUMMYFUNCTION("""COMPUTED_VALUE"""),"4EME1") -> 4EME1 | G3: =IFERROR(__xludf.DUMMYFUNCTION("""COMPUTED_VALUE"""),"4ème") -> 4ème | H3: =IFERROR(__xludf.DUMMYFUNCTION("""COMPUTED_VALUE"""),"Lycée Français Jacques Prévert de Saly » Collège » 4ème » Générale") -> Lycée Français Jacques Prévert de Saly » Collège » 4ème » Générale | I3: =IFERROR(__xludf.DUMMYFUNCTION("""COMPUTED_VALUE"""),"LVA Anglais") -> LVA Anglais | J3: =IFERROR(__xludf.DUMMYFUNCTION("""COMPUTED_VALUE"""),"LVB Espagnol") -> LVB Espagnol | N3: =IFERROR(__xludf.DUMMYFUNCTION("""COMPUTED_VALUE"""),"Fille") -> Fille | P3: =IFERROR(__xludf.DUMMYFUNCTION("""COMPUTED_VALUE"""),"FRANCE") -> FRANCE | R3: =IFERROR(__xludf.DUMMYFUNCTION("""COMPUTED_VALUE"""),"eiden.aboudou-sarr@lfjpsaly.org") -> eiden.aboudou-sarr@lfjpsaly.org | S3: =IFERROR(__xludf.DUMMYFUNCTION("""COMPUTED_VALUE"""),"+221") -> +221 | T3: =IFERROR(__xludf.DUMMYFUNCTION("""COMPUTED_VALUE"""),"SARR-MESSAOUDI Licka") -> SARR-MESSAOUDI Licka | U3: =IFERROR(__xludf.DUMMYFUNCTION("""COMPUTED_VALUE"""),"ABOUDOU Karim") -> ABOUDOU Karim | V3: =IFERROR(__xludf.DUMMYFUNCTION("""COMPUTED_VALUE"""),"yacine.licka@gmail.com") -> yacine.licka@gmail.com | W3: =IFERROR(__xludf.DUMMYFUNCTION("""COMPUTED_VALUE"""),"kaboudou@gmail.com") -> kaboudou@gmail.com | X3: =IFERROR(__xludf.DUMMYFUNCTION("""COMPUTED_VALUE"""),"+221 78 912 91 27") -> +221 78 912 91 27 | Y3: =IFERROR(__xludf.DUMMYFUNCTION("""COMPUTED_VALUE"""),"+33 6 83 79 93 69") -> +33 6 83 79 93 69 | Z3: =IFERROR(__xludf.DUMMYFUNCTION("""COMPUTED_VALUE"""),"+221 77 593 91 07") -> +221 77 593 91 07 | AB3: =IFERROR(__xludf.DUMMYFUNCTION("""COMPUTED_VALUE"""),30479) -> 30479 | AC3: =IFERROR(__xludf.DUMMYFUNCTION("""COMPUTED_VALUE"""),29782) -> 29782 | AD3: =IFERROR(__xludf.DUMMYFUNCTION("""COMPUTED_VALUE"""),"MERE") -> MERE | AE3: =IFERROR(__xludf.DUMMYFUNCTION("""COMPUTED_VALUE"""),"PERE") -> PERE | AF3: =IFERROR(__xludf.DUMMYFUNCTION("""COMPUTED_VALUE"""),"FRANCE") -> FRANCE | AG3: =IFERROR(__xludf.DUMMYFUNCTION("""COMPUTED_VALUE"""),"FRANCE") -> FRANCE | AJ3: =IFERROR(__xludf.DUMMYFUNCTION("""COMPUTED_VALUE"""),"F1626") -> F1626 | AK3: =IFERROR(__xludf.DUMMYFUNCTION("""COMPUTED_VALUE"""),"Marié(e)") -> Marié(e) | AL3: =IFERROR(__xludf.DUMMYFUNCTION("""COMPUTED_VALUE"""),"Célibataire") -> Célibataire | AM3: =IFERROR(__xludf.DUMMYFUNCTION("""COMPUTED_VALUE"""),"F1626") -> F1626
A4: =IFERROR(__xludf.DUMMYFUNCTION("""COMPUTED_VALUE"""),"ACETO Awa") -> ACETO Awa | B4: =IFERROR(__xludf.DUMMYFUNCTION("""COMPUTED_VALUE"""),"ACETO") -> ACETO | C4: =IFERROR(__xludf.DUMMYFUNCTION("""COMPUTED_VALUE"""),"Awa") -> Awa | D4: =IFERROR(__xludf.DUMMYFUNCTION("""COMPUTED_VALUE"""),"11654S2208") -> 11654S2208 | E4: =IFERROR(__xludf.DUMMYFUNCTION("""COMPUTED_VALUE"""),39797) -> 39797 | F4: =IFERROR(__xludf.DUMMYFUNCTION("""COMPUTED_VALUE"""),"TERMINALE2") -> TERMINALE2 | G4: =IFERROR(__xludf.DUMMYFUNCTION("""COMPUTED_VALUE"""),"Terminale") -> Terminale | H4: =IFERROR(__xludf.DUMMYFUNCTION("""COMPUTED_VALUE"""),"Lycée Français Jacques Prévert de Saly » Lycée » Terminale » Générale") -> Lycée Français Jacques Prévert de Saly » Lycée » Terminale » Générale | I4: =IFERROR(__xludf.DUMMYFUNCTION("""COMPUTED_VALUE"""),"LVA Anglais") -> LVA Anglais | J4: =IFERROR(__xludf.DUMMYFUNCTION("""COMPUTED_VALUE"""),"LVB Espagnol") -> LVB Espagnol | M4: =IFERROR(__xludf.DUMMYFUNCTION("""COMPUTED_VALUE"""),"SPE HGGSP, SPE SES") -> SPE HGGSP, SPE SES | N4: =IFERROR(__xludf.DUMMYFUNCTION("""COMPUTED_VALUE"""),"Fille") -> Fille | P4: =IFERROR(__xludf.DUMMYFUNCTION("""COMPUTED_VALUE"""),"FRANCE") -> FRANCE | Q4: =IFERROR(__xludf.DUMMYFUNCTION("""COMPUTED_VALUE"""),"SENEGAL") -> SENEGAL | R4: =IFERROR(__xludf.DUMMYFUNCTION("""COMPUTED_VALUE"""),"awa.aceto@lfjpsaly.org") -> awa.aceto@lfjpsaly.org | T4: =IFERROR(__xludf.DUMMYFUNCTION("""COMPUTED_VALUE"""),"ACETO Héléne") -> ACETO Héléne | U4: =IFERROR(__xludf.DUMMYFUNCTION("""COMPUTED_VALUE"""),"ACETO Pascal") -> ACETO Pascal | V4: =IFERROR(__xludf.DUMMYFUNCTION("""COMPUTED_VALUE"""),"h.aceto@yahoo.fr") -> h.aceto@yahoo.fr | W4: =IFERROR(__xludf.DUMMYFUNCTION("""COMPUTED_VALUE"""),"h.aceto@yahoo.fr") -> h.aceto@yahoo.fr | X4: =IFERROR(__xludf.DUMMYFUNCTION("""COMPUTED_VALUE"""),"+33 6 09 88 38 56") -> +33 6 09 88 38 56 | Y4: =IFERROR(__xludf.DUMMYFUNCTION("""COMPUTED_VALUE"""),"+33 6 09 88 38 56") -> +33 6 09 88 38 56 | Z4: =IFERROR(__xludf.DUMMYFUNCTION("""COMPUTED_VALUE"""),"+33 6 09 88 38 56") -> +33 6 09 88 38 56 | AA4: =IFERROR(__xludf.DUMMYFUNCTION("""COMPUTED_VALUE"""),"+33 6 09 88 38 56") -> +33 6 09 88 38 56 | AB4: =IFERROR(__xludf.DUMMYFUNCTION("""COMPUTED_VALUE"""),16677) -> 16677 | AC4: =IFERROR(__xludf.DUMMYFUNCTION("""COMPUTED_VALUE"""),20505) -> 20505 | AD4: =IFERROR(__xludf.DUMMYFUNCTION("""COMPUTED_VALUE"""),"Non spécifiée") -> Non spécifiée | AE4: =IFERROR(__xludf.DUMMYFUNCTION("""COMPUTED_VALUE"""),"Non spécifiée") -> Non spécifiée | AF4: =IFERROR(__xludf.DUMMYFUNCTION("""COMPUTED_VALUE"""),"FRANCE") -> FRANCE | AG4: =IFERROR(__xludf.DUMMYFUNCTION("""COMPUTED_VALUE"""),"FRANCE") -> FRANCE | AJ4: =IFERROR(__xludf.DUMMYFUNCTION("""COMPUTED_VALUE"""),"U11654") -> U11654 | AK4: =IFERROR(__xludf.DUMMYFUNCTION("""COMPUTED_VALUE"""),"Marié(e)") -> Marié(e) | AL4: =IFERROR(__xludf.DUMMYFUNCTION("""COMPUTED_VALUE"""),"Marié(e)") -> Marié(e) | AM4: =IFERROR(__xludf.DUMMYFUNCTION("""COMPUTED_VALUE"""),"U11654") -> U11654
A5: =IFERROR(__xludf.DUMMYFUNCTION("""COMPUTED_VALUE"""),"ACHCAR Gérard") -> ACHCAR Gérard | B5: =IFERROR(__xludf.DUMMYFUNCTION("""COMPUTED_VALUE"""),"ACHCAR") -> ACHCAR | C5: =IFERROR(__xludf.DUMMYFUNCTION("""COMPUTED_VALUE"""),"Gérard") -> Gérard | D5: =IFERROR(__xludf.DUMMYFUNCTION("""COMPUTED_VALUE"""),"11742S2436") -> 11742S2436 | E5: =IFERROR(__xludf.DUMMYFUNCTION("""COMPUTED_VALUE"""),43808) -> 43808 | F5: =IFERROR(__xludf.DUMMYFUNCTION("""COMPUTED_VALUE"""),"CP") -> CP | G5: =IFERROR(__xludf.DUMMYFUNCTION("""COMPUTED_VALUE"""),"CP") -> CP | H5: =IFERROR(__xludf.DUMMYFUNCTION("""COMPUTED_VALUE"""),"Lycée Français Jacques Prévert de Saly » Elémentaire » CP » Générale") -> Lycée Français Jacques Prévert de Saly » Elémentaire » CP » Générale | N5: =IFERROR(__xludf.DUMMYFUNCTION("""COMPUTED_VALUE"""),"Garçon") -> Garçon | P5: =IFERROR(__xludf.DUMMYFUNCTION("""COMPUTED_VALUE"""),"FRANCE") -> FRANCE | S5: =IFERROR(__xludf.DUMMYFUNCTION("""COMPUTED_VALUE"""),"+221") -> +221 | T5: =IFERROR(__xludf.DUMMYFUNCTION("""COMPUTED_VALUE"""),"ACHCAR Elsa") -> ACHCAR Elsa | U5: =IFERROR(__xludf.DUMMYFUNCTION("""COMPUTED_VALUE"""),"ACHCAR Fabrice") -> ACHCAR Fabrice | V5: =IFERROR(__xludf.DUMMYFUNCTION("""COMPUTED_VALUE"""),"elsakamouh@gmail.com") -> elsakamouh@gmail.com | W5: =IFERROR(__xludf.DUMMYFUNCTION("""COMPUTED_VALUE"""),"achcarfabrice@hotmail.com") -> achcarfabrice@hotmail.com | X5: =IFERROR(__xludf.DUMMYFUNCTION("""COMPUTED_VALUE"""),"+221 71 009 85 39") -> +221 71 009 85 39 | Y5: =IFERROR(__xludf.DUMMYFUNCTION("""COMPUTED_VALUE"""),"+221 78 918 80 60") -> +221 78 918 80 60 | Z5: =IFERROR(__xludf.DUMMYFUNCTION("""COMPUTED_VALUE"""),"+33 6 23 29 02 74") -> +33 6 23 29 02 74 | AA5: =IFERROR(__xludf.DUMMYFUNCTION("""COMPUTED_VALUE"""),"+223 66 75 38 68") -> +223 66 75 38 68 | AB5: =IFERROR(__xludf.DUMMYFUNCTION("""COMPUTED_VALUE"""),33024) -> 33024 | AC5: =IFERROR(__xludf.DUMMYFUNCTION("""COMPUTED_VALUE"""),33022) -> 33022 | AD5: =IFERROR(__xludf.DUMMYFUNCTION("""COMPUTED_VALUE"""),"MERE") -> MERE | AE5: =IFERROR(__xludf.DUMMYFUNCTION("""COMPUTED_VALUE"""),"PERE") -> PERE | AF5: =IFERROR(__xludf.DUMMYFUNCTION("""COMPUTED_VALUE"""),"FRANCE") -> FRANCE | AG5: =IFERROR(__xludf.DUMMYFUNCTION("""COMPUTED_VALUE"""),"FRANCE") -> FRANCE | AJ5: =IFERROR(__xludf.DUMMYFUNCTION("""COMPUTED_VALUE"""),"U11742") -> U11742 | AK5: =IFERROR(__xludf.DUMMYFUNCTION("""COMPUTED_VALUE"""),"Marié(e)") -> Marié(e) | AL5: =IFERROR(__xludf.DUMMYFUNCTION("""COMPUTED_VALUE"""),"Marié(e)") -> Marié(e) | AM5: =IFERROR(__xludf.DUMMYFUNCTION("""COMPUTED_VALUE"""),"U11742") -> U11742
A6: =IFERROR(__xludf.DUMMYFUNCTION("""COMPUTED_VALUE"""),"AGEE Luka") -> AGEE Luka | B6: =IFERROR(__xludf.DUMMYFUNCTION("""COMPUTED_VALUE"""),"AGEE") -> AGEE | C6: =IFERROR(__xludf.DUMMYFUNCTION("""COMPUTED_VALUE"""),"Luka") -> Luka | D6: =IFERROR(__xludf.DUMMYFUNCTION("""COMPUTED_VALUE"""),"1116E1") -> 1116E1 | E6: =IFERROR(__xludf.DUMMYFUNCTION("""COMPUTED_VALUE"""),43819) -> 43819 | F6: =IFERROR(__xludf.DUMMYFUNCTION("""COMPUTED_VALUE"""),"CP") -> CP | G6: =IFERROR(__xludf.DUMMYFUNCTION("""COMPUTED_VALUE"""),"CP") -> CP | H6: =IFERROR(__xludf.DUMMYFUNCTION("""COMPUTED_VALUE"""),"Lycée Français Jacques Prévert de Saly » Elémentaire » CP » Générale") -> Lycée Français Jacques Prévert de Saly » Elémentaire » CP » Générale | N6: =IFERROR(__xludf.DUMMYFUNCTION("""COMPUTED_VALUE"""),"Garçon") -> Garçon | P6: =IFERROR(__xludf.DUMMYFUNCTION("""COMPUTED_VALUE"""),"FRANCE") -> FRANCE | Q6: =IFERROR(__xludf.DUMMYFUNCTION("""COMPUTED_VALUE"""),"ETATS-UNIS") -> ETATS-UNIS | T6: =IFERROR(__xludf.DUMMYFUNCTION("""COMPUTED_VALUE"""),"AGEE Céline") -> AGEE Céline | U6: =IFERROR(__xludf.DUMMYFUNCTION("""COMPUTED_VALUE"""),"AGEE John") -> AGEE John | V6: =IFERROR(__xludf.DUMMYFUNCTION("""COMPUTED_VALUE"""),"voyagee.fr@gmail.com") -> voyagee.fr@gmail.com | W6: =IFERROR(__xludf.DUMMYFUNCTION("""COMPUTED_VALUE"""),"john@agee.us") -> john@agee.us | X6: =IFERROR(__xludf.DUMMYFUNCTION("""COMPUTED_VALUE"""),"+221 77 690 01 41") -> +221 77 690 01 41 | Y6: =IFERROR(__xludf.DUMMYFUNCTION("""COMPUTED_VALUE"""),"77 114 76 25") -> 77 114 76 25 | Z6: =IFERROR(__xludf.DUMMYFUNCTION("""COMPUTED_VALUE"""),"+221") -> +221 | AB6: =IFERROR(__xludf.DUMMYFUNCTION("""COMPUTED_VALUE"""),33754) -> 33754 | AC6: =IFERROR(__xludf.DUMMYFUNCTION("""COMPUTED_VALUE"""),30463) -> 30463 | AD6: =IFERROR(__xludf.DUMMYFUNCTION("""COMPUTED_VALUE"""),"MERE") -> MERE | AE6: =IFERROR(__xludf.DUMMYFUNCTION("""COMPUTED_VALUE"""),"PERE") -> PERE | AF6: =IFERROR(__xludf.DUMMYFUNCTION("""COMPUTED_VALUE"""),"FRANCE") -> FRANCE | AG6: =IFERROR(__xludf.DUMMYFUNCTION("""COMPUTED_VALUE"""),"ETATS-UNIS") -> ETATS-UNIS | AH6: =IFERROR(__xludf.DUMMYFUNCTION("""COMPUTED_VALUE"""),"ETATS-UNIS") -> ETATS-UNIS | AJ6: =IFERROR(__xludf.DUMMYFUNCTION("""COMPUTED_VALUE"""),"F1116") -> F1116 | AK6: =IFERROR(__xludf.DUMMYFUNCTION("""COMPUTED_VALUE"""),"Marié(e)") -> Marié(e) | AL6: =IFERROR(__xludf.DUMMYFUNCTION("""COMPUTED_VALUE"""),"Marié(e)") -> Marié(e) | AM6: =IFERROR(__xludf.DUMMYFUNCTION("""COMPUTED_VALUE"""),"F1116") -> F1116
A7: =IFERROR(__xludf.DUMMYFUNCTION("""COMPUTED_VALUE"""),"AGUESSE Hugo") -> AGUESSE Hugo | B7: =IFERROR(__xludf.DUMMYFUNCTION("""COMPUTED_VALUE"""),"AGUESSE") -> AGUESSE | C7: =IFERROR(__xludf.DUMMYFUNCTION("""COMPUTED_VALUE"""),"Hugo") -> Hugo | D7: =IFERROR(__xludf.DUMMYFUNCTION("""COMPUTED_VALUE"""),"11899S2784") -> 11899S2784 | E7: =IFERROR(__xludf.DUMMYFUNCTION("""COMPUTED_VALUE"""),41526) -> 41526 | F7: =IFERROR(__xludf.DUMMYFUNCTION("""COMPUTED_VALUE"""),"5EME2") -> 5EME2 | G7: =IFERROR(__xludf.DUMMYFUNCTION("""COMPUTED_VALUE"""),"5ème") -> 5ème | H7: =IFERROR(__xludf.DUMMYFUNCTION("""COMPUTED_VALUE"""),"Lycée Français Jacques Prévert de Saly » Collège » 5ème » Générale") -> Lycée Français Jacques Prévert de Saly » Collège » 5ème » Générale | I7: =IFERROR(__xludf.DUMMYFUNCTION("""COMPUTED_VALUE"""),"LVA Anglais") -> LVA Anglais | J7: =IFERROR(__xludf.DUMMYFUNCTION("""COMPUTED_VALUE"""),"LVB Espagnol") -> LVB Espagnol | N7: =IFERROR(__xludf.DUMMYFUNCTION("""COMPUTED_VALUE"""),"Garçon") -> Garçon | P7: =IFERROR(__xludf.DUMMYFUNCTION("""COMPUTED_VALUE"""),"FRANCE") -> FRANCE | R7: =IFERROR(__xludf.DUMMYFUNCTION("""COMPUTED_VALUE"""),"hugo.aguesse@lfjpsaly.org") -> hugo.aguesse@lfjpsaly.org | S7: =IFERROR(__xludf.DUMMYFUNCTION("""COMPUTED_VALUE"""),"+221") -> +221 | T7: =IFERROR(__xludf.DUMMYFUNCTION("""COMPUTED_VALUE"""),"AGUESSE Ariane") -> AGUESSE Ariane | U7: =IFERROR(__xludf.DUMMYFUNCTION("""COMPUTED_VALUE"""),"AGUESSE Nicolas") -> AGUESSE Nicolas | V7: =IFERROR(__xludf.DUMMYFUNCTION("""COMPUTED_VALUE"""),"arianeve@hotmail.fr") -> arianeve@hotmail.fr | W7: =IFERROR(__xludf.DUMMYFUNCTION("""COMPUTED_VALUE"""),"naguesse@hotmail.fr") -> naguesse@hotmail.fr | X7: =IFERROR(__xludf.DUMMYFUNCTION("""COMPUTED_VALUE"""),"+221 78 384 53 22") -> +221 78 384 53 22 | Y7: =IFERROR(__xludf.DUMMYFUNCTION("""COMPUTED_VALUE"""),"+594 694 35 10 33") -> +594 694 35 10 33 | Z7: =IFERROR(__xludf.DUMMYFUNCTION("""COMPUTED_VALUE"""),"+221") -> +221 | AA7: =IFERROR(__xludf.DUMMYFUNCTION("""COMPUTED_VALUE"""),"+221") -> +221 | AB7: =IFERROR(__xludf.DUMMYFUNCTION("""COMPUTED_VALUE"""),27946) -> 27946 | AC7: =IFERROR(__xludf.DUMMYFUNCTION("""COMPUTED_VALUE"""),29079) -> 29079 | AD7: =IFERROR(__xludf.DUMMYFUNCTION("""COMPUTED_VALUE"""),"MERE") -> MERE | AE7: =IFERROR(__xludf.DUMMYFUNCTION("""COMPUTED_VALUE"""),"PERE") -> PERE | AF7: =IFERROR(__xludf.DUMMYFUNCTION("""COMPUTED_VALUE"""),"FRANCE") -> FRANCE | AG7: =IFERROR(__xludf.DUMMYFUNCTION("""COMPUTED_VALUE"""),"FRANCE") -> FRANCE | AJ7: =IFERROR(__xludf.DUMMYFUNCTION("""COMPUTED_VALUE"""),"U11899") -> U11899 | AK7: =IFERROR(__xludf.DUMMYFUNCTION("""COMPUTED_VALUE"""),"Marié(e)") -> Marié(e) | AL7: =IFERROR(__xludf.DUMMYFUNCTION("""COMPUTED_VALUE"""),"Marié(e)") -> Marié(e) | AM7: =IFERROR(__xludf.DUMMYFUNCTION("""COMPUTED_VALUE"""),"U11899") -> U11899
A8: =IFERROR(__xludf.DUMMYFUNCTION("""COMPUTED_VALUE"""),"AGUESSE Julie") -> AGUESSE Julie | B8: =IFERROR(__xludf.DUMMYFUNCTION("""COMPUTED_VALUE"""),"AGUESSE") -> AGUESSE | C8: =IFERROR(__xludf.DUMMYFUNCTION("""COMPUTED_VALUE"""),"Julie") -> Julie | D8: =IFERROR(__xludf.DUMMYFUNCTION("""COMPUTED_VALUE"""),"11899S2783") -> 11899S2783 | E8: =IFERROR(__xludf.DUMMYFUNCTION("""COMPUTED_VALUE"""),40128) -> 40128 | F8: =IFERROR(__xludf.DUMMYFUNCTION("""COMPUTED_VALUE"""),"1ERE2") -> 1ERE2 | G8: =IFERROR(__xludf.DUMMYFUNCTION("""COMPUTED_VALUE"""),"1ère") -> 1ère | H8: =IFERROR(__xludf.DUMMYFUNCTION("""COMPUTED_VALUE"""),"Lycée Français Jacques Prévert de Saly » Lycée » 1ère » Générale") -> Lycée Français Jacques Prévert de Saly » Lycée » 1ère » Générale | I8: =IFERROR(__xludf.DUMMYFUNCTION("""COMPUTED_VALUE"""),"LVA Anglais") -> LVA Anglais | J8: =IFERROR(__xludf.DUMMYFUNCTION("""COMPUTED_VALUE"""),"LVB Espagnol") -> LVB Espagnol | M8: =IFERROR(__xludf.DUMMYFUNCTION("""COMPUTED_VALUE"""),"SPE MATHS, SPE SVT, SPE SPC") -> SPE MATHS, SPE SVT, SPE SPC | N8: =IFERROR(__xludf.DUMMYFUNCTION("""COMPUTED_VALUE"""),"Fille") -> Fille | P8: =IFERROR(__xludf.DUMMYFUNCTION("""COMPUTED_VALUE"""),"FRANCE") -> FRANCE | R8: =IFERROR(__xludf.DUMMYFUNCTION("""COMPUTED_VALUE"""),"julie.aguesse@lfjpsaly.org") -> julie.aguesse@lfjpsaly.org | S8: =IFERROR(__xludf.DUMMYFUNCTION("""COMPUTED_VALUE"""),"+221") -> +221 | T8: =IFERROR(__xludf.DUMMYFUNCTION("""COMPUTED_VALUE"""),"AGUESSE Ariane") -> AGUESSE Ariane | U8: =IFERROR(__xludf.DUMMYFUNCTION("""COMPUTED_VALUE"""),"AGUESSE Nicolas") -> AGUESSE Nicolas | V8: =IFERROR(__xludf.DUMMYFUNCTION("""COMPUTED_VALUE"""),"arianeve@hotmail.fr") -> arianeve@hotmail.fr | W8: =IFERROR(__xludf.DUMMYFUNCTION("""COMPUTED_VALUE"""),"naguesse@hotmail.fr") -> naguesse@hotmail.fr | X8: =IFERROR(__xludf.DUMMYFUNCTION("""COMPUTED_VALUE"""),"+221 78 384 53 22") -> +221 78 384 53 22 | Y8: =IFERROR(__xludf.DUMMYFUNCTION("""COMPUTED_VALUE"""),"+594 694 35 10 33") -> +594 694 35 10 33 | Z8: =IFERROR(__xludf.DUMMYFUNCTION("""COMPUTED_VALUE"""),"+221") -> +221 | AA8: =IFERROR(__xludf.DUMMYFUNCTION("""COMPUTED_VALUE"""),"+221") -> +221 | AB8: =IFERROR(__xludf.DUMMYFUNCTION("""COMPUTED_VALUE"""),27946) -> 27946 | AC8: =IFERROR(__xludf.DUMMYFUNCTION("""COMPUTED_VALUE"""),29079) -> 29079 | AD8: =IFERROR(__xludf.DUMMYFUNCTION("""COMPUTED_VALUE"""),"MERE") -> MERE | AE8: =IFERROR(__xludf.DUMMYFUNCTION("""COMPUTED_VALUE"""),"PERE") -> PERE | AF8: =IFERROR(__xludf.DUMMYFUNCTION("""COMPUTED_VALUE"""),"FRANCE") -> FRANCE | AG8: =IFERROR(__xludf.DUMMYFUNCTION("""COMPUTED_VALUE"""),"FRANCE") -> FRANCE | AJ8: =IFERROR(__xludf.DUMMYFUNCTION("""COMPUTED_VALUE"""),"U11899") -> U11899 | AK8: =IFERROR(__xludf.DUMMYFUNCTION("""COMPUTED_VALUE"""),"Marié(e)") -> Marié(e) | AL8: =IFERROR(__xludf.DUMMYFUNCTION("""COMPUTED_VALUE"""),"Marié(e)") -> Marié(e) | AM8: =IFERROR(__xludf.DUMMYFUNCTION("""COMPUTED_VALUE"""),"U11899") -> U11899
A9: =IFERROR(__xludf.DUMMYFUNCTION("""COMPUTED_VALUE"""),"ALLIER Faustine") -> ALLIER Faustine | B9: =IFERROR(__xludf.DUMMYFUNCTION("""COMPUTED_VALUE"""),"ALLIER") -> ALLIER | C9: =IFERROR(__xludf.DUMMYFUNCTION("""COMPUTED_VALUE"""),"Faustine") -> Faustine | D9: =IFERROR(__xludf.DUMMYFUNCTION("""COMPUTED_VALUE"""),"1119E1") -> 1119E1 | E9: =IFERROR(__xludf.DUMMYFUNCTION("""COMPUTED_VALUE"""),39948) -> 39948 | F9: =IFERROR(__xludf.DUMMYFUNCTION("""COMPUTED_VALUE"""),"1ERE1") -> 1ERE1 | G9: =IFERROR(__xludf.DUMMYFUNCTION("""COMPUTED_VALUE"""),"1ère") -> 1ère | H9: =IFERROR(__xludf.DUMMYFUNCTION("""COMPUTED_VALUE"""),"Lycée Français Jacques Prévert de Saly » Lycée » 1ère » Générale") -> Lycée Français Jacques Prévert de Saly » Lycée » 1ère » Générale | I9: =IFERROR(__xludf.DUMMYFUNCTION("""COMPUTED_VALUE"""),"LVA Anglais") -> LVA Anglais | J9: =IFERROR(__xludf.DUMMYFUNCTION("""COMPUTED_VALUE"""),"LVB Espagnol") -> LVB Espagnol | M9: =IFERROR(__xludf.DUMMYFUNCTION("""COMPUTED_VALUE"""),"SPE HGGSP, SPE MATHS, SPE SES") -> SPE HGGSP, SPE MATHS, SPE SES | N9: =IFERROR(__xludf.DUMMYFUNCTION("""COMPUTED_VALUE"""),"Fille") -> Fille | P9: =IFERROR(__xludf.DUMMYFUNCTION("""COMPUTED_VALUE"""),"FRANCE") -> FRANCE | R9: =IFERROR(__xludf.DUMMYFUNCTION("""COMPUTED_VALUE"""),"faustine.allier@lfjpsaly.org") -> faustine.allier@lfjpsaly.org | S9: =IFERROR(__xludf.DUMMYFUNCTION("""COMPUTED_VALUE"""),"+221 78 185 36 17") -> +221 78 185 36 17 | T9: =IFERROR(__xludf.DUMMYFUNCTION("""COMPUTED_VALUE"""),"VALLET Margaret") -> VALLET Margaret | U9: =IFERROR(__xludf.DUMMYFUNCTION("""COMPUTED_VALUE"""),"ALLIER Pascal") -> ALLIER Pascal | V9: =IFERROR(__xludf.DUMMYFUNCTION("""COMPUTED_VALUE"""),"margaux@adjanaresort.com") -> margaux@adjanaresort.com | W9: =IFERROR(__xludf.DUMMYFUNCTION("""COMPUTED_VALUE"""),"pascal.allier@free.fr") -> pascal.allier@free.fr | X9: =IFERROR(__xludf.DUMMYFUNCTION("""COMPUTED_VALUE"""),"+221 78 185 36 17") -> +221 78 185 36 17 | Y9: =IFERROR(__xludf.DUMMYFUNCTION("""COMPUTED_VALUE"""),"+33 6 17 92 68 90") -> +33 6 17 92 68 90 | Z9: =IFERROR(__xludf.DUMMYFUNCTION("""COMPUTED_VALUE"""),"+221 78 185 36 17") -> +221 78 185 36 17 | AA9: =IFERROR(__xludf.DUMMYFUNCTION("""COMPUTED_VALUE"""),"+221") -> +221 | AB9: =IFERROR(__xludf.DUMMYFUNCTION("""COMPUTED_VALUE"""),27515) -> 27515 | AC9: =IFERROR(__xludf.DUMMYFUNCTION("""COMPUTED_VALUE"""),46267) -> 46267 | AD9: =IFERROR(__xludf.DUMMYFUNCTION("""COMPUTED_VALUE"""),"MERE") -> MERE | AE9: =IFERROR(__xludf.DUMMYFUNCTION("""COMPUTED_VALUE"""),"PERE") -> PERE | AF9: =IFERROR(__xludf.DUMMYFUNCTION("""COMPUTED_VALUE"""),"FRANCE") -> FRANCE | AG9: =IFERROR(__xludf.DUMMYFUNCTION("""COMPUTED_VALUE"""),"FRANCE") -> FRANCE | AJ9: =IFERROR(__xludf.DUMMYFUNCTION("""COMPUTED_VALUE"""),"F1119") -> F1119 | AK9: =IFERROR(__xludf.DUMMYFUNCTION("""COMPUTED_VALUE"""),"Célibataire") -> Célibataire | AL9: =IFERROR(__xludf.DUMMYFUNCTION("""COMPUTED_VALUE"""),"Célibataire") -> Célibataire | AM9: =IFERROR(__xludf.DUMMYFUNCTION("""COMPUTED_VALUE"""),"F1119") -> F1119
A10: =IFERROR(__xludf.DUMMYFUNCTION("""COMPUTED_VALUE"""),"AMADOU SALL Daha-Ibrahim") -> AMADOU SALL Daha-Ibrahim | B10: =IFERROR(__xludf.DUMMYFUNCTION("""COMPUTED_VALUE"""),"AMADOU SALL") -> AMADOU SALL | C10: =IFERROR(__xludf.DUMMYFUNCTION("""COMPUTED_VALUE"""),"Daha-Ibrahim") -> Daha-Ibrahim | D10: =IFERROR(__xludf.DUMMYFUNCTION("""COMPUTED_VALUE"""),"1120E4") -> 1120E4 | E10: =IFERROR(__xludf.DUMMYFUNCTION("""COMPUTED_VALUE"""),44647) -> 44647 | F10: =IFERROR(__xludf.DUMMYFUNCTION("""COMPUTED_VALUE"""),"Mat 1") -> Mat 1 | G10: =IFERROR(__xludf.DUMMYFUNCTION("""COMPUTED_VALUE"""),"PS") -> PS | H10: =IFERROR(__xludf.DUMMYFUNCTION("""COMPUTED_VALUE"""),"Lycée Français Jacques Prévert de Saly » Maternelle » PS » Générale") -> Lycée Français Jacques Prévert de Saly » Maternelle » PS » Générale | N10: =IFERROR(__xludf.DUMMYFUNCTION("""COMPUTED_VALUE"""),"Garçon") -> Garçon | P10: =IFERROR(__xludf.DUMMYFUNCTION("""COMPUTED_VALUE"""),"FRANCE") -> FRANCE | S10: =IFERROR(__xludf.DUMMYFUNCTION("""COMPUTED_VALUE"""),"+221") -> +221 | T10: =IFERROR(__xludf.DUMMYFUNCTION("""COMPUTED_VALUE"""),"SALL Coudy") -> SALL Coudy | U10: =IFERROR(__xludf.DUMMYFUNCTION("""COMPUTED_VALUE"""),"AMADOU Arouna") -> AMADOU Arouna | V10: =IFERROR(__xludf.DUMMYFUNCTION("""COMPUTED_VALUE"""),"csall27@outlook.fr") -> csall27@outlook.fr | W10: =IFERROR(__xludf.DUMMYFUNCTION("""COMPUTED_VALUE"""),"arounadaha78@gmail.com") -> arounadaha78@gmail.com | X10: =IFERROR(__xludf.DUMMYFUNCTION("""COMPUTED_VALUE"""),"+33 1 30 94 18 70") -> +33 1 30 94 18 70 | Y10: =IFERROR(__xludf.DUMMYFUNCTION("""COMPUTED_VALUE"""),"+33 6 60 25 55 96") -> +33 6 60 25 55 96 | Z10: =IFERROR(__xludf.DUMMYFUNCTION("""COMPUTED_VALUE"""),"+221 78 125 11 41") -> +221 78 125 11 41 | AA10: =IFERROR(__xludf.DUMMYFUNCTION("""COMPUTED_VALUE"""),"+221 78 125 11 41") -> +221 78 125 11 41 | AB10: =IFERROR(__xludf.DUMMYFUNCTION("""COMPUTED_VALUE"""),32321) -> 32321 | AC10: =IFERROR(__xludf.DUMMYFUNCTION("""COMPUTED_VALUE"""),31815) -> 31815 | AD10: =IFERROR(__xludf.DUMMYFUNCTION("""COMPUTED_VALUE"""),"MERE") -> MERE | AE10: =IFERROR(__xludf.DUMMYFUNCTION("""COMPUTED_VALUE"""),"PERE") -> PERE | AF10: =IFERROR(__xludf.DUMMYFUNCTION("""COMPUTED_VALUE"""),"FRANCE") -> FRANCE | AG10: =IFERROR(__xludf.DUMMYFUNCTION("""COMPUTED_VALUE"""),"FRANCE") -> FRANCE | AH10: =IFERROR(__xludf.DUMMYFUNCTION("""COMPUTED_VALUE"""),"SENEGAL") -> SENEGAL | AI10: =IFERROR(__xludf.DUMMYFUNCTION("""COMPUTED_VALUE"""),"SENEGAL") -> SENEGAL | AJ10: =IFERROR(__xludf.DUMMYFUNCTION("""COMPUTED_VALUE"""),"F1120") -> F1120 | AK10: =IFERROR(__xludf.DUMMYFUNCTION("""COMPUTED_VALUE"""),"CONCUBINAGE") -> CONCUBINAGE | AL10: =IFERROR(__xludf.DUMMYFUNCTION("""COMPUTED_VALUE"""),"CONCUBINAGE") -> CONCUBINAGE | AM10: =IFERROR(__xludf.DUMMYFUNCTION("""COMPUTED_VALUE"""),"F1120") -> F1120
A11: =IFERROR(__xludf.DUMMYFUNCTION("""COMPUTED_VALUE"""),"AMADOU-SALL Fatyma") -> AMADOU-SALL Fatyma | B11: =IFERROR(__xludf.DUMMYFUNCTION("""COMPUTED_VALUE"""),"AMADOU-SALL") -> AMADOU-SALL | C11: =IFERROR(__xludf.DUMMYFUNCTION("""COMPUTED_VALUE"""),"Fatyma") -> Fatyma | D11: =IFERROR(__xludf.DUMMYFUNCTION("""COMPUTED_VALUE"""),"1120E1") -> 1120E1 | E11: =IFERROR(__xludf.DUMMYFUNCTION("""COMPUTED_VALUE"""),41716) -> 41716 | F11: =IFERROR(__xludf.DUMMYFUNCTION("""COMPUTED_VALUE"""),"6EME1") -> 6EME1 | G11: =IFERROR(__xludf.DUMMYFUNCTION("""COMPUTED_VALUE"""),"6ème") -> 6ème | H11: =IFERROR(__xludf.DUMMYFUNCTION("""COMPUTED_VALUE"""),"Lycée Français Jacques Prévert de Saly » Collège » 6ème » Générale") -> Lycée Français Jacques Prévert de Saly » Collège » 6ème » Générale | I11: =IFERROR(__xludf.DUMMYFUNCTION("""COMPUTED_VALUE"""),"LVA Anglais") -> LVA Anglais | J11: =IFERROR(__xludf.DUMMYFUNCTION("""COMPUTED_VALUE"""),"LVB Espagnol") -> LVB Espagnol | N11: =IFERROR(__xludf.DUMMYFUNCTION("""COMPUTED_VALUE"""),"Fille") -> Fille | P11: =IFERROR(__xludf.DUMMYFUNCTION("""COMPUTED_VALUE"""),"FRANCE") -> FRANCE | R11: =IFERROR(__xludf.DUMMYFUNCTION("""COMPUTED_VALUE"""),"fatyma.amadou-sall@lfjpsaly.org") -> fatyma.amadou-sall@lfjpsaly.org | T11: =IFERROR(__xludf.DUMMYFUNCTION("""COMPUTED_VALUE"""),"SALL Coudy") -> SALL Coudy | U11: =IFERROR(__xludf.DUMMYFUNCTION("""COMPUTED_VALUE"""),"AMADOU Arouna") -> AMADOU Arouna | V11: =IFERROR(__xludf.DUMMYFUNCTION("""COMPUTED_VALUE"""),"csall27@outlook.fr") -> csall27@outlook.fr | W11: =IFERROR(__xludf.DUMMYFUNCTION("""COMPUTED_VALUE"""),"arounadaha78@gmail.com") -> arounadaha78@gmail.com | X11: =IFERROR(__xludf.DUMMYFUNCTION("""COMPUTED_VALUE"""),"+33 1 30 94 18 70") -> +33 1 30 94 18 70 | Y11: =IFERROR(__xludf.DUMMYFUNCTION("""COMPUTED_VALUE"""),"+33 6 60 25 55 96") -> +33 6 60 25 55 96 | Z11: =IFERROR(__xludf.DUMMYFUNCTION("""COMPUTED_VALUE"""),"+221 78 125 11 41") -> +221 78 125 11 41 | AA11: =IFERROR(__xludf.DUMMYFUNCTION("""COMPUTED_VALUE"""),"+221 78 125 11 41") -> +221 78 125 11 41 | AB11: =IFERROR(__xludf.DUMMYFUNCTION("""COMPUTED_VALUE"""),32321) -> 32321 | AC11: =IFERROR(__xludf.DUMMYFUNCTION("""COMPUTED_VALUE"""),31815) -> 31815 | AD11: =IFERROR(__xludf.DUMMYFUNCTION("""COMPUTED_VALUE"""),"MERE") -> MERE | AE11: =IFERROR(__xludf.DUMMYFUNCTION("""COMPUTED_VALUE"""),"PERE") -> PERE | AF11: =IFERROR(__xludf.DUMMYFUNCTION("""COMPUTED_VALUE"""),"FRANCE") -> FRANCE | AG11: =IFERROR(__xludf.DUMMYFUNCTION("""COMPUTED_VALUE"""),"FRANCE") -> FRANCE | AH11: =IFERROR(__xludf.DUMMYFUNCTION("""COMPUTED_VALUE"""),"SENEGAL") -> SENEGAL | AI11: =IFERROR(__xludf.DUMMYFUNCTION("""COMPUTED_VALUE"""),"SENEGAL") -> SENEGAL | AJ11: =IFERROR(__xludf.DUMMYFUNCTION("""COMPUTED_VALUE"""),"F1120") -> F1120 | AK11: =IFERROR(__xludf.DUMMYFUNCTION("""COMPUTED_VALUE"""),"CONCUBINAGE") -> CONCUBINAGE | AL11: =IFERROR(__xludf.DUMMYFUNCTION("""COMPUTED_VALUE"""),"CONCUBINAGE") -> CONCUBINAGE | AM11: =IFERROR(__xludf.DUMMYFUNCTION("""COMPUTED_VALUE"""),"F1120") -> F1120
A12: =IFERROR(__xludf.DUMMYFUNCTION("""COMPUTED_VALUE"""),"AMADOU-SALL Moussa") -> AMADOU-SALL Moussa | B12: =IFERROR(__xludf.DUMMYFUNCTION("""COMPUTED_VALUE"""),"AMADOU-SALL") -> AMADOU-SALL | C12: =IFERROR(__xludf.DUMMYFUNCTION("""COMPUTED_VALUE"""),"Moussa") -> Moussa | D12: =IFERROR(__xludf.DUMMYFUNCTION("""COMPUTED_VALUE"""),"1120E2") -> 1120E2 | E12: =IFERROR(__xludf.DUMMYFUNCTION("""COMPUTED_VALUE"""),41021) -> 41021 | F12: =IFERROR(__xludf.DUMMYFUNCTION("""COMPUTED_VALUE"""),"4EME1") -> 4EME1 | G12: =IFERROR(__xludf.DUMMYFUNCTION("""COMPUTED_VALUE"""),"4ème") -> 4ème | H12: =IFERROR(__xludf.DUMMYFUNCTION("""COMPUTED_VALUE"""),"Lycée Français Jacques Prévert de Saly » Collège » 4ème » Générale") -> Lycée Français Jacques Prévert de Saly » Collège » 4ème » Générale | I12: =IFERROR(__xludf.DUMMYFUNCTION("""COMPUTED_VALUE"""),"LVA Anglais") -> LVA Anglais | J12: =IFERROR(__xludf.DUMMYFUNCTION("""COMPUTED_VALUE"""),"LVB Espagnol") -> LVB Espagnol | N12: =IFERROR(__xludf.DUMMYFUNCTION("""COMPUTED_VALUE"""),"Garçon") -> Garçon | P12: =IFERROR(__xludf.DUMMYFUNCTION("""COMPUTED_VALUE"""),"FRANCE") -> FRANCE | R12: =IFERROR(__xludf.DUMMYFUNCTION("""COMPUTED_VALUE"""),"moussa.amadou-sall@lfjpsaly.org") -> moussa.amadou-sall@lfjpsaly.org | T12: =IFERROR(__xludf.DUMMYFUNCTION("""COMPUTED_VALUE"""),"AMADOU Arouna") -> AMADOU Arouna | U12: =IFERROR(__xludf.DUMMYFUNCTION("""COMPUTED_VALUE"""),"SALL Coudy") -> SALL Coudy | V12: =IFERROR(__xludf.DUMMYFUNCTION("""COMPUTED_VALUE"""),"arounadaha78@gmail.com") -> arounadaha78@gmail.com | W12: =IFERROR(__xludf.DUMMYFUNCTION("""COMPUTED_VALUE"""),"csall27@outlook.fr") -> csall27@outlook.fr | X12: =IFERROR(__xludf.DUMMYFUNCTION("""COMPUTED_VALUE"""),"+33 6 60 25 55 96") -> +33 6 60 25 55 96 | Y12: =IFERROR(__xludf.DUMMYFUNCTION("""COMPUTED_VALUE"""),"+33 1 30 94 18 70") -> +33 1 30 94 18 70 | Z12: =IFERROR(__xludf.DUMMYFUNCTION("""COMPUTED_VALUE"""),"+221 78 125 11 41") -> +221 78 125 11 41 | AA12: =IFERROR(__xludf.DUMMYFUNCTION("""COMPUTED_VALUE"""),"+221 78 125 11 41") -> +221 78 125 11 41 | AB12: =IFERROR(__xludf.DUMMYFUNCTION("""COMPUTED_VALUE"""),31815) -> 31815 | AC12: =IFERROR(__xludf.DUMMYFUNCTION("""COMPUTED_VALUE"""),32321) -> 32321 | AD12: =IFERROR(__xludf.DUMMYFUNCTION("""COMPUTED_VALUE"""),"PERE") -> PERE | AE12: =IFERROR(__xludf.DUMMYFUNCTION("""COMPUTED_VALUE"""),"MERE") -> MERE | AF12: =IFERROR(__xludf.DUMMYFUNCTION("""COMPUTED_VALUE"""),"FRANCE") -> FRANCE | AG12: =IFERROR(__xludf.DUMMYFUNCTION("""COMPUTED_VALUE"""),"FRANCE") -> FRANCE | AH12: =IFERROR(__xludf.DUMMYFUNCTION("""COMPUTED_VALUE"""),"SENEGAL") -> SENEGAL | AI12: =IFERROR(__xludf.DUMMYFUNCTION("""COMPUTED_VALUE"""),"SENEGAL") -> SENEGAL | AJ12: =IFERROR(__xludf.DUMMYFUNCTION("""COMPUTED_VALUE"""),"F1120") -> F1120 | AK12: =IFERROR(__xludf.DUMMYFUNCTION("""COMPUTED_VALUE"""),"CONCUBINAGE") -> CONCUBINAGE | AL12: =IFERROR(__xludf.DUMMYFUNCTION("""COMPUTED_VALUE"""),"CONCUBINAGE") -> CONCUBINAGE | AM12: =IFERROR(__xludf.DUMMYFUNCTION("""COMPUTED_VALUE"""),"F1120") -> F1120
A13: =IFERROR(__xludf.DUMMYFUNCTION("""COMPUTED_VALUE"""),"AMADOU-SALL Soumaya-Thila") -> AMADOU-SALL Soumaya-Thila | B13: =IFERROR(__xludf.DUMMYFUNCTION("""COMPUTED_VALUE"""),"AMADOU-SALL") -> AMADOU-SALL | C13: =IFERROR(__xludf.DUMMYFUNCTION("""COMPUTED_VALUE"""),"Soumaya-Thila") -> Soumaya-Thila | D13: =IFERROR(__xludf.DUMMYFUNCTION("""COMPUTED_VALUE"""),"1120E3") -> 1120E3 | E13: =IFERROR(__xludf.DUMMYFUNCTION("""COMPUTED_VALUE"""),43542) -> 43542 | F13: =IFERROR(__xludf.DUMMYFUNCTION("""COMPUTED_VALUE"""),"CP") -> CP | G13: =IFERROR(__xludf.DUMMYFUNCTION("""COMPUTED_VALUE"""),"CP") -> CP | H13: =IFERROR(__xludf.DUMMYFUNCTION("""COMPUTED_VALUE"""),"Lycée Français Jacques Prévert de Saly » Elémentaire » CP » Générale") -> Lycée Français Jacques Prévert de Saly » Elémentaire » CP » Générale | N13: =IFERROR(__xludf.DUMMYFUNCTION("""COMPUTED_VALUE"""),"Fille") -> Fille | P13: =IFERROR(__xludf.DUMMYFUNCTION("""COMPUTED_VALUE"""),"FRANCE") -> FRANCE | T13: =IFERROR(__xludf.DUMMYFUNCTION("""COMPUTED_VALUE"""),"SALL Coudy") -> SALL Coudy | U13: =IFERROR(__xludf.DUMMYFUNCTION("""COMPUTED_VALUE"""),"AMADOU Arouna") -> AMADOU Arouna | V13: =IFERROR(__xludf.DUMMYFUNCTION("""COMPUTED_VALUE"""),"csall27@outlook.fr") -> csall27@outlook.fr | W13: =IFERROR(__xludf.DUMMYFUNCTION("""COMPUTED_VALUE"""),"arounadaha78@gmail.com") -> arounadaha78@gmail.com | X13: =IFERROR(__xludf.DUMMYFUNCTION("""COMPUTED_VALUE"""),"+33 1 30 94 18 70") -> +33 1 30 94 18 70 | Y13: =IFERROR(__xludf.DUMMYFUNCTION("""COMPUTED_VALUE"""),"+33 6 60 25 55 96") -> +33 6 60 25 55 96 | Z13: =IFERROR(__xludf.DUMMYFUNCTION("""COMPUTED_VALUE"""),"+221 78 125 11 41") -> +221 78 125 11 41 | AA13: =IFERROR(__xludf.DUMMYFUNCTION("""COMPUTED_VALUE"""),"+221 78 125 11 41") -> +221 78 125 11 41 | AB13: =IFERROR(__xludf.DUMMYFUNCTION("""COMPUTED_VALUE"""),32321) -> 32321 | AC13: =IFERROR(__xludf.DUMMYFUNCTION("""COMPUTED_VALUE"""),31815) -> 31815 | AD13: =IFERROR(__xludf.DUMMYFUNCTION("""COMPUTED_VALUE"""),"MERE") -> MERE | AE13: =IFERROR(__xludf.DUMMYFUNCTION("""COMPUTED_VALUE"""),"PERE") -> PERE | AF13: =IFERROR(__xludf.DUMMYFUNCTION("""COMPUTED_VALUE"""),"FRANCE") -> FRANCE | AG13: =IFERROR(__xludf.DUMMYFUNCTION("""COMPUTED_VALUE"""),"FRANCE") -> FRANCE | AH13: =IFERROR(__xludf.DUMMYFUNCTION("""COMPUTED_VALUE"""),"SENEGAL") -> SENEGAL | AI13: =IFERROR(__xludf.DUMMYFUNCTION("""COMPUTED_VALUE"""),"SENEGAL") -> SENEGAL | AJ13: =IFERROR(__xludf.DUMMYFUNCTION("""COMPUTED_VALUE"""),"F1120") -> F1120 | AK13: =IFERROR(__xludf.DUMMYFUNCTION("""COMPUTED_VALUE"""),"CONCUBINAGE") -> CONCUBINAGE | AL13: =IFERROR(__xludf.DUMMYFUNCTION("""COMPUTED_VALUE"""),"CONCUBINAGE") -> CONCUBINAGE | AM13: =IFERROR(__xludf.DUMMYFUNCTION("""COMPUTED_VALUE"""),"F1120") -> F1120
A14: =IFERROR(__xludf.DUMMYFUNCTION("""COMPUTED_VALUE"""),"ANATO Noa Elianah Mondukpe") -> ANATO Noa Elianah Mondukpe | B14: =IFERROR(__xludf.DUMMYFUNCTION("""COMPUTED_VALUE"""),"ANATO") -> ANATO | C14: =IFERROR(__xludf.DUMMYFUNCTION("""COMPUTED_VALUE"""),"Noa Elianah Mondukpe") -> Noa Elianah Mondukpe | D14: =IFERROR(__xludf.DUMMYFUNCTION("""COMPUTED_VALUE"""),"1123E3") -> 1123E3 | E14: =IFERROR(__xludf.DUMMYFUNCTION("""COMPUTED_VALUE"""),43872) -> 43872 | F14: =IFERROR(__xludf.DUMMYFUNCTION("""COMPUTED_VALUE"""),"Mat 3") -> Mat 3 | G14: =IFERROR(__xludf.DUMMYFUNCTION("""COMPUTED_VALUE"""),"GS") -> GS | H14: =IFERROR(__xludf.DUMMYFUNCTION("""COMPUTED_VALUE"""),"Lycée Français Jacques Prévert de Saly » Maternelle » GS » Générale") -> Lycée Français Jacques Prévert de Saly » Maternelle » GS » Générale | N14: =IFERROR(__xludf.DUMMYFUNCTION("""COMPUTED_VALUE"""),"Fille") -> Fille | P14: =IFERROR(__xludf.DUMMYFUNCTION("""COMPUTED_VALUE"""),"BENIN") -> BENIN | T14: =IFERROR(__xludf.DUMMYFUNCTION("""COMPUTED_VALUE"""),"ANATO Sevinin Yannick") -> ANATO Sevinin Yannick | U14: =IFERROR(__xludf.DUMMYFUNCTION("""COMPUTED_VALUE"""),"ANATO Rachel Carole Grace") -> ANATO Rachel Carole Grace | V14: =IFERROR(__xludf.DUMMYFUNCTION("""COMPUTED_VALUE"""),"yannickanato@gmail.com") -> yannickanato@gmail.com | W14: =IFERROR(__xludf.DUMMYFUNCTION("""COMPUTED_VALUE"""),"rachelboucarianato@gmail.com") -> rachelboucarianato@gmail.com | X14: =IFERROR(__xludf.DUMMYFUNCTION("""COMPUTED_VALUE"""),"+221 78 470 01 01") -> +221 78 470 01 01 | Y14: =IFERROR(__xludf.DUMMYFUNCTION("""COMPUTED_VALUE"""),"+221 78 470 03 03") -> +221 78 470 03 03 | Z14: =IFERROR(__xludf.DUMMYFUNCTION("""COMPUTED_VALUE"""),"+221 78 470 01 01") -> +221 78 470 01 01 | AA14: =IFERROR(__xludf.DUMMYFUNCTION("""COMPUTED_VALUE"""),"+221 78 470 03 03") -> +221 78 470 03 03 | AB14: =IFERROR(__xludf.DUMMYFUNCTION("""COMPUTED_VALUE"""),32461) -> 32461 | AC14: =IFERROR(__xludf.DUMMYFUNCTION("""COMPUTED_VALUE"""),33857) -> 33857 | AD14: =IFERROR(__xludf.DUMMYFUNCTION("""COMPUTED_VALUE"""),"PERE") -> PERE | AE14: =IFERROR(__xludf.DUMMYFUNCTION("""COMPUTED_VALUE"""),"MERE") -> MERE | AF14: =IFERROR(__xludf.DUMMYFUNCTION("""COMPUTED_VALUE"""),"BENIN") -> BENIN | AG14: =IFERROR(__xludf.DUMMYFUNCTION("""COMPUTED_VALUE"""),"BENIN") -> BENIN | AH14: =IFERROR(__xludf.DUMMYFUNCTION("""COMPUTED_VALUE"""),"BENIN") -> BENIN | AJ14: =IFERROR(__xludf.DUMMYFUNCTION("""COMPUTED_VALUE"""),"F1123") -> F1123 | AK14: =IFERROR(__xludf.DUMMYFUNCTION("""COMPUTED_VALUE"""),"Marié(e)") -> Marié(e) | AL14: =IFERROR(__xludf.DUMMYFUNCTION("""COMPUTED_VALUE"""),"Marié(e)") -> Marié(e) | AM14: =IFERROR(__xludf.DUMMYFUNCTION("""COMPUTED_VALUE"""),"F1123") -> F1123
A15: =IFERROR(__xludf.DUMMYFUNCTION("""COMPUTED_VALUE"""),"ANATO Yoann Stachys Dagbemin") -> ANATO Yoann Stachys Dagbemin | B15: =IFERROR(__xludf.DUMMYFUNCTION("""COMPUTED_VALUE"""),"ANATO") -> ANATO | C15: =IFERROR(__xludf.DUMMYFUNCTION("""COMPUTED_VALUE"""),"Yoann Stachys Dagbemin") -> Yoann Stachys Dagbemin | D15: =IFERROR(__xludf.DUMMYFUNCTION("""COMPUTED_VALUE"""),"1123E4") -> 1123E4 | E15: =IFERROR(__xludf.DUMMYFUNCTION("""COMPUTED_VALUE"""),43025) -> 43025 | F15: =IFERROR(__xludf.DUMMYFUNCTION("""COMPUTED_VALUE"""),"CE2") -> CE2 | G15: =IFERROR(__xludf.DUMMYFUNCTION("""COMPUTED_VALUE"""),"CE2") -> CE2 | H15: =IFERROR(__xludf.DUMMYFUNCTION("""COMPUTED_VALUE"""),"Lycée Français Jacques Prévert de Saly » Elémentaire » CE2 » Générale") -> Lycée Français Jacques Prévert de Saly » Elémentaire » CE2 » Générale | N15: =IFERROR(__xludf.DUMMYFUNCTION("""COMPUTED_VALUE"""),"Garçon") -> Garçon | P15: =IFERROR(__xludf.DUMMYFUNCTION("""COMPUTED_VALUE"""),"BENIN") -> BENIN | T15: =IFERROR(__xludf.DUMMYFUNCTION("""COMPUTED_VALUE"""),"ANATO Sevinin Yannick") -> ANATO Sevinin Yannick | U15: =IFERROR(__xludf.DUMMYFUNCTION("""COMPUTED_VALUE"""),"ANATO Rachel Carole Grace") -> ANATO Rachel Carole Grace | V15: =IFERROR(__xludf.DUMMYFUNCTION("""COMPUTED_VALUE"""),"yannickanato@gmail.com") -> yannickanato@gmail.com | W15: =IFERROR(__xludf.DUMMYFUNCTION("""COMPUTED_VALUE"""),"rachelboucarianato@gmail.com") -> rachelboucarianato@gmail.com | X15: =IFERROR(__xludf.DUMMYFUNCTION("""COMPUTED_VALUE"""),"+221 78 470 01 01") -> +221 78 470 01 01 | Y15: =IFERROR(__xludf.DUMMYFUNCTION("""COMPUTED_VALUE"""),"+221 78 470 03 03") -> +221 78 470 03 03 | Z15: =IFERROR(__xludf.DUMMYFUNCTION("""COMPUTED_VALUE"""),"+221 78 470 01 01") -> +221 78 470 01 01 | AA15: =IFERROR(__xludf.DUMMYFUNCTION("""COMPUTED_VALUE"""),"+221 78 470 03 03") -> +221 78 470 03 03 | AB15: =IFERROR(__xludf.DUMMYFUNCTION("""COMPUTED_VALUE"""),32461) -> 32461 | AC15: =IFERROR(__xludf.DUMMYFUNCTION("""COMPUTED_VALUE"""),33857) -> 33857 | AD15: =IFERROR(__xludf.DUMMYFUNCTION("""COMPUTED_VALUE"""),"PERE") -> PERE | AE15: =IFERROR(__xludf.DUMMYFUNCTION("""COMPUTED_VALUE"""),"MERE") -> MERE | AF15: =IFERROR(__xludf.DUMMYFUNCTION("""COMPUTED_VALUE"""),"BENIN") -> BENIN | AG15: =IFERROR(__xludf.DUMMYFUNCTION("""COMPUTED_VALUE"""),"BENIN") -> BENIN | AH15: =IFERROR(__xludf.DUMMYFUNCTION("""COMPUTED_VALUE"""),"BENIN") -> BENIN | AJ15: =IFERROR(__xludf.DUMMYFUNCTION("""COMPUTED_VALUE"""),"F1123") -> F1123 | AK15: =IFERROR(__xludf.DUMMYFUNCTION("""COMPUTED_VALUE"""),"Marié(e)") -> Marié(e) | AL15: =IFERROR(__xludf.DUMMYFUNCTION("""COMPUTED_VALUE"""),"Marié(e)") -> Marié(e) | AM15: =IFERROR(__xludf.DUMMYFUNCTION("""COMPUTED_VALUE"""),"F1123") -> F1123
A16: =IFERROR(__xludf.DUMMYFUNCTION("""COMPUTED_VALUE"""),"ANIZI Mohamed") -> ANIZI Mohamed | B16: =IFERROR(__xludf.DUMMYFUNCTION("""COMPUTED_VALUE"""),"ANIZI") -> ANIZI | C16: =IFERROR(__xludf.DUMMYFUNCTION("""COMPUTED_VALUE"""),"Mohamed") -> Mohamed | D16: =IFERROR(__xludf.DUMMYFUNCTION("""COMPUTED_VALUE"""),"1124E1") -> 1124E1 | E16: =IFERROR(__xludf.DUMMYFUNCTION("""COMPUTED_VALUE"""),42434) -> 42434 | F16: =IFERROR(__xludf.DUMMYFUNCTION("""COMPUTED_VALUE"""),"CM1B") -> CM1B | G16: =IFERROR(__xludf.DUMMYFUNCTION("""COMPUTED_VALUE"""),"CM1") -> CM1 | H16: =IFERROR(__xludf.DUMMYFUNCTION("""COMPUTED_VALUE"""),"Lycée Français Jacques Prévert de Saly » Elémentaire » CM1 » Générale") -> Lycée Français Jacques Prévert de Saly » Elémentaire » CM1 » Générale | N16: =IFERROR(__xludf.DUMMYFUNCTION("""COMPUTED_VALUE"""),"Garçon") -> Garçon | P16: =IFERROR(__xludf.DUMMYFUNCTION("""COMPUTED_VALUE"""),"TUNISIE") -> TUNISIE | T16: =IFERROR(__xludf.DUMMYFUNCTION("""COMPUTED_VALUE"""),"HAMROUNI Riheme") -> HAMROUNI Riheme | U16: =IFERROR(__xludf.DUMMYFUNCTION("""COMPUTED_VALUE"""),"ANIZI Aymen") -> ANIZI Aymen | V16: =IFERROR(__xludf.DUMMYFUNCTION("""COMPUTED_VALUE"""),"rihemehamrouni@outlook.com") -> rihemehamrouni@outlook.com | W16: =IFERROR(__xludf.DUMMYFUNCTION("""COMPUTED_VALUE"""),"aymenanizi.aa@gmail.com") -> aymenanizi.aa@gmail.com | X16: =IFERROR(__xludf.DUMMYFUNCTION("""COMPUTED_VALUE"""),"+221 77 566 00 36") -> +221 77 566 00 36 | Y16: =IFERROR(__xludf.DUMMYFUNCTION("""COMPUTED_VALUE"""),"+216 21 997 232") -> +216 21 997 232 | Z16: =IFERROR(__xludf.DUMMYFUNCTION("""COMPUTED_VALUE"""),"+216 29 133 870") -> +216 29 133 870 | AB16: =IFERROR(__xludf.DUMMYFUNCTION("""COMPUTED_VALUE"""),30975) -> 30975 | AC16: =IFERROR(__xludf.DUMMYFUNCTION("""COMPUTED_VALUE"""),31372) -> 31372 | AD16: =IFERROR(__xludf.DUMMYFUNCTION("""COMPUTED_VALUE"""),"MERE") -> MERE | AE16: =IFERROR(__xludf.DUMMYFUNCTION("""COMPUTED_VALUE"""),"PERE") -> PERE | AF16: =IFERROR(__xludf.DUMMYFUNCTION("""COMPUTED_VALUE"""),"TUNISIE") -> TUNISIE | AG16: =IFERROR(__xludf.DUMMYFUNCTION("""COMPUTED_VALUE"""),"TUNISIE") -> TUNISIE | AJ16: =IFERROR(__xludf.DUMMYFUNCTION("""COMPUTED_VALUE"""),"F1124") -> F1124 | AK16: =IFERROR(__xludf.DUMMYFUNCTION("""COMPUTED_VALUE"""),"Marié(e)") -> Marié(e) | AL16: =IFERROR(__xludf.DUMMYFUNCTION("""COMPUTED_VALUE"""),"Marié(e)") -> Marié(e) | AM16: =IFERROR(__xludf.DUMMYFUNCTION("""COMPUTED_VALUE"""),"F1124") -> F1124
A17: =IFERROR(__xludf.DUMMYFUNCTION("""COMPUTED_VALUE"""),"APACK Nayla") -> APACK Nayla | B17: =IFERROR(__xludf.DUMMYFUNCTION("""COMPUTED_VALUE"""),"APACK") -> APACK | C17: =IFERROR(__xludf.DUMMYFUNCTION("""COMPUTED_VALUE"""),"Nayla") -> Nayla | D17: =IFERROR(__xludf.DUMMYFUNCTION("""COMPUTED_VALUE"""),"1125E1") -> 1125E1 | E17: =IFERROR(__xludf.DUMMYFUNCTION("""COMPUTED_VALUE"""),39626) -> 39626 | F17: =IFERROR(__xludf.DUMMYFUNCTION("""COMPUTED_VALUE"""),"TERMINALE2") -> TERMINALE2 | G17: =IFERROR(__xludf.DUMMYFUNCTION("""COMPUTED_VALUE"""),"Terminale") -> Terminale | H17: =IFERROR(__xludf.DUMMYFUNCTION("""COMPUTED_VALUE"""),"Lycée Français Jacques Prévert de Saly » Lycée » Terminale » Générale") -> Lycée Français Jacques Prévert de Saly » Lycée » Terminale » Générale | I17: =IFERROR(__xludf.DUMMYFUNCTION("""COMPUTED_VALUE"""),"LVA Anglais") -> LVA Anglais | J17: =IFERROR(__xludf.DUMMYFUNCTION("""COMPUTED_VALUE"""),"LVB Espagnol") -> LVB Espagnol | M17: =IFERROR(__xludf.DUMMYFUNCTION("""COMPUTED_VALUE"""),"SPE HGGSP, SPE SES") -> SPE HGGSP, SPE SES | N17: =IFERROR(__xludf.DUMMYFUNCTION("""COMPUTED_VALUE"""),"Fille") -> Fille | P17: =IFERROR(__xludf.DUMMYFUNCTION("""COMPUTED_VALUE"""),"FRANCE") -> FRANCE | Q17: =IFERROR(__xludf.DUMMYFUNCTION("""COMPUTED_VALUE"""),"BELGIQUE") -> BELGIQUE | R17: =IFERROR(__xludf.DUMMYFUNCTION("""COMPUTED_VALUE"""),"nayla.apack@lfjpsaly.org") -> nayla.apack@lfjpsaly.org | T17: =IFERROR(__xludf.DUMMYFUNCTION("""COMPUTED_VALUE"""),"SWEETLOVE Yasmine") -> SWEETLOVE Yasmine | U17: =IFERROR(__xludf.DUMMYFUNCTION("""COMPUTED_VALUE"""),"APACK Philippe") -> APACK Philippe | V17: =IFERROR(__xludf.DUMMYFUNCTION("""COMPUTED_VALUE"""),"yasmine.sweetlove@icloud.com") -> yasmine.sweetlove@icloud.com | W17: =IFERROR(__xludf.DUMMYFUNCTION("""COMPUTED_VALUE"""),"philippe.apack@yahoo.fr") -> philippe.apack@yahoo.fr | X17: =IFERROR(__xludf.DUMMYFUNCTION("""COMPUTED_VALUE"""),"+221 78 388 98 62") -> +221 78 388 98 62 | Y17: =IFERROR(__xludf.DUMMYFUNCTION("""COMPUTED_VALUE"""),"+221 78 483 68 96") -> +221 78 483 68 96 | AB17: =IFERROR(__xludf.DUMMYFUNCTION("""COMPUTED_VALUE"""),28753) -> 28753 | AC17: =IFERROR(__xludf.DUMMYFUNCTION("""COMPUTED_VALUE"""),24494) -> 24494 | AD17: =IFERROR(__xludf.DUMMYFUNCTION("""COMPUTED_VALUE"""),"MERE") -> MERE | AE17: =IFERROR(__xludf.DUMMYFUNCTION("""COMPUTED_VALUE"""),"PERE") -> PERE | AF17: =IFERROR(__xludf.DUMMYFUNCTION("""COMPUTED_VALUE"""),"BELGIQUE") -> BELGIQUE | AG17: =IFERROR(__xludf.DUMMYFUNCTION("""COMPUTED_VALUE"""),"FRANCE") -> FRANCE | AJ17: =IFERROR(__xludf.DUMMYFUNCTION("""COMPUTED_VALUE"""),"F1125") -> F1125 | AK17: =IFERROR(__xludf.DUMMYFUNCTION("""COMPUTED_VALUE"""),"Séparé(e)") -> Séparé(e) | AL17: =IFERROR(__xludf.DUMMYFUNCTION("""COMPUTED_VALUE"""),"Séparé(e)") -> Séparé(e) | AM17: =IFERROR(__xludf.DUMMYFUNCTION("""COMPUTED_VALUE"""),"F1125") -> F1125
A18: =IFERROR(__xludf.DUMMYFUNCTION("""COMPUTED_VALUE"""),"ARRON Hélène") -> ARRON Hélène | B18: =IFERROR(__xludf.DUMMYFUNCTION("""COMPUTED_VALUE"""),"ARRON") -> ARRON | C18: =IFERROR(__xludf.DUMMYFUNCTION("""COMPUTED_VALUE"""),"Hélène") -> Hélène | D18: =IFERROR(__xludf.DUMMYFUNCTION("""COMPUTED_VALUE"""),"1126E1") -> 1126E1 | E18: =IFERROR(__xludf.DUMMYFUNCTION("""COMPUTED_VALUE"""),39704) -> 39704 | F18: =IFERROR(__xludf.DUMMYFUNCTION("""COMPUTED_VALUE"""),"TERMINALE1") -> TERMINALE1 | G18: =IFERROR(__xludf.DUMMYFUNCTION("""COMPUTED_VALUE"""),"Terminale") -> Terminale | H18: =IFERROR(__xludf.DUMMYFUNCTION("""COMPUTED_VALUE"""),"Lycée Français Jacques Prévert de Saly » Lycée » Terminale » Générale") -> Lycée Français Jacques Prévert de Saly » Lycée » Terminale » Générale | I18: =IFERROR(__xludf.DUMMYFUNCTION("""COMPUTED_VALUE"""),"LVA Anglais") -> LVA Anglais | J18: =IFERROR(__xludf.DUMMYFUNCTION("""COMPUTED_VALUE"""),"LVB Espagnol") -> LVB Espagnol | K18: =IFERROR(__xludf.DUMMYFUNCTION("""COMPUTED_VALUE"""),"MATHS EXPERTES") -> MATHS EXPERTES | M18: =IFERROR(__xludf.DUMMYFUNCTION("""COMPUTED_VALUE"""),"SPE MATHS, SPE SVT") -> SPE MATHS, SPE SVT | N18: =IFERROR(__xludf.DUMMYFUNCTION("""COMPUTED_VALUE"""),"Fille") -> Fille | P18: =IFERROR(__xludf.DUMMYFUNCTION("""COMPUTED_VALUE"""),"FRANCE") -> FRANCE | R18: =IFERROR(__xludf.DUMMYFUNCTION("""COMPUTED_VALUE"""),"helene.arron@lfjpsaly.org") -> helene.arron@lfjpsaly.org | T18: =IFERROR(__xludf.DUMMYFUNCTION("""COMPUTED_VALUE"""),"SFEIR Aurélia") -> SFEIR Aurélia | U18: =IFERROR(__xludf.DUMMYFUNCTION("""COMPUTED_VALUE"""),"ARRON Arne") -> ARRON Arne | V18: =IFERROR(__xludf.DUMMYFUNCTION("""COMPUTED_VALUE"""),"aureliasfeir@gmail.com") -> aureliasfeir@gmail.com | W18: =IFERROR(__xludf.DUMMYFUNCTION("""COMPUTED_VALUE"""),"aureliasfeir@gmail.com") -> aureliasfeir@gmail.com | X18: =IFERROR(__xludf.DUMMYFUNCTION("""COMPUTED_VALUE"""),"+221 77 690 99 48") -> +221 77 690 99 48 | Y18: =IFERROR(__xludf.DUMMYFUNCTION("""COMPUTED_VALUE"""),"+221 77 524 54 16") -> +221 77 524 54 16 | AB18: =IFERROR(__xludf.DUMMYFUNCTION("""COMPUTED_VALUE"""),27633) -> 27633 | AC18: =IFERROR(__xludf.DUMMYFUNCTION("""COMPUTED_VALUE"""),30669) -> 30669 | AD18: =IFERROR(__xludf.DUMMYFUNCTION("""COMPUTED_VALUE"""),"MERE") -> MERE | AE18: =IFERROR(__xludf.DUMMYFUNCTION("""COMPUTED_VALUE"""),"PERE") -> PERE | AF18: =IFERROR(__xludf.DUMMYFUNCTION("""COMPUTED_VALUE"""),"FRANCE") -> FRANCE | AG18: =IFERROR(__xludf.DUMMYFUNCTION("""COMPUTED_VALUE"""),"BELGIQUE") -> BELGIQUE | AJ18: =IFERROR(__xludf.DUMMYFUNCTION("""COMPUTED_VALUE"""),"F1126") -> F1126 | AK18: =IFERROR(__xludf.DUMMYFUNCTION("""COMPUTED_VALUE"""),"Divorcée") -> Divorcée | AL18: =IFERROR(__xludf.DUMMYFUNCTION("""COMPUTED_VALUE"""),"Divorcée") -> Divorcée | AM18: =IFERROR(__xludf.DUMMYFUNCTION("""COMPUTED_VALUE"""),"F1126") -> F1126
A19: =IFERROR(__xludf.DUMMYFUNCTION("""COMPUTED_VALUE"""),"ASSELIN Kevin") -> ASSELIN Kevin | B19: =IFERROR(__xludf.DUMMYFUNCTION("""COMPUTED_VALUE"""),"ASSELIN") -> ASSELIN | C19: =IFERROR(__xludf.DUMMYFUNCTION("""COMPUTED_VALUE"""),"Kevin") -> Kevin | D19: =IFERROR(__xludf.DUMMYFUNCTION("""COMPUTED_VALUE"""),"1127E1") -> 1127E1 | E19: =IFERROR(__xludf.DUMMYFUNCTION("""COMPUTED_VALUE"""),41257) -> 41257 | F19: =IFERROR(__xludf.DUMMYFUNCTION("""COMPUTED_VALUE"""),"4EME1") -> 4EME1 | G19: =IFERROR(__xludf.DUMMYFUNCTION("""COMPUTED_VALUE"""),"4ème") -> 4ème | H19: =IFERROR(__xludf.DUMMYFUNCTION("""COMPUTED_VALUE"""),"Lycée Français Jacques Prévert de Saly » Collège » 4ème » Générale") -> Lycée Français Jacques Prévert de Saly » Collège » 4ème » Générale | I19: =IFERROR(__xludf.DUMMYFUNCTION("""COMPUTED_VALUE"""),"LVA Anglais") -> LVA Anglais | J19: =IFERROR(__xludf.DUMMYFUNCTION("""COMPUTED_VALUE"""),"LVB Espagnol") -> LVB Espagnol | N19: =IFERROR(__xludf.DUMMYFUNCTION("""COMPUTED_VALUE"""),"Garçon") -> Garçon | P19: =IFERROR(__xludf.DUMMYFUNCTION("""COMPUTED_VALUE"""),"FRANCE") -> FRANCE | Q19: =IFERROR(__xludf.DUMMYFUNCTION("""COMPUTED_VALUE"""),"SENEGAL") -> SENEGAL | R19: =IFERROR(__xludf.DUMMYFUNCTION("""COMPUTED_VALUE"""),"kevin.asselin@lfjpsaly.org") -> kevin.asselin@lfjpsaly.org | T19: =IFERROR(__xludf.DUMMYFUNCTION("""COMPUTED_VALUE"""),"ASSELIN Andre") -> ASSELIN Andre | U19: =IFERROR(__xludf.DUMMYFUNCTION("""COMPUTED_VALUE"""),"TOMBO Annela") -> TOMBO Annela | V19: =IFERROR(__xludf.DUMMYFUNCTION("""COMPUTED_VALUE"""),"chaletduchocolat@orange.fr") -> chaletduchocolat@orange.fr | W19: =IFERROR(__xludf.DUMMYFUNCTION("""COMPUTED_VALUE"""),"anneladania@gmail.com") -> anneladania@gmail.com | X19: =IFERROR(__xludf.DUMMYFUNCTION("""COMPUTED_VALUE"""),"+33 6 85 33 89 77") -> +33 6 85 33 89 77 | Y19: =IFERROR(__xludf.DUMMYFUNCTION("""COMPUTED_VALUE"""),"+221 77 765 02 17") -> +221 77 765 02 17 | Z19: =IFERROR(__xludf.DUMMYFUNCTION("""COMPUTED_VALUE"""),"+221 77 766 37 60") -> +221 77 766 37 60 | AA19: =IFERROR(__xludf.DUMMYFUNCTION("""COMPUTED_VALUE"""),"+221 78 125 25 60") -> +221 78 125 25 60 | AB19: =IFERROR(__xludf.DUMMYFUNCTION("""COMPUTED_VALUE"""),20793) -> 20793 | AC19: =IFERROR(__xludf.DUMMYFUNCTION("""COMPUTED_VALUE"""),35069) -> 35069 | AD19: =IFERROR(__xludf.DUMMYFUNCTION("""COMPUTED_VALUE"""),"PERE") -> PERE | AE19: =IFERROR(__xludf.DUMMYFUNCTION("""COMPUTED_VALUE"""),"AUTRE LIEN") -> AUTRE LIEN | AF19: =IFERROR(__xludf.DUMMYFUNCTION("""COMPUTED_VALUE"""),"FRANCE") -> FRANCE | AG19: =IFERROR(__xludf.DUMMYFUNCTION("""COMPUTED_VALUE"""),"MADAGASCAR") -> MADAGASCAR | AJ19: =IFERROR(__xludf.DUMMYFUNCTION("""COMPUTED_VALUE"""),"F1127") -> F1127 | AK19: =IFERROR(__xludf.DUMMYFUNCTION("""COMPUTED_VALUE"""),"Divorcée") -> Divorcée | AL19: =IFERROR(__xludf.DUMMYFUNCTION("""COMPUTED_VALUE"""),"Célibataire") -> Célibataire | AM19: =IFERROR(__xludf.DUMMYFUNCTION("""COMPUTED_VALUE"""),"F1127") -> F1127
A20: =IFERROR(__xludf.DUMMYFUNCTION("""COMPUTED_VALUE"""),"AUBRY Albert Akoi Agamemnon") -> AUBRY Albert Akoi Agamemnon | B20: =IFERROR(__xludf.DUMMYFUNCTION("""COMPUTED_VALUE"""),"AUBRY") -> AUBRY | C20: =IFERROR(__xludf.DUMMYFUNCTION("""COMPUTED_VALUE"""),"Albert Akoi Agamemnon") -> Albert Akoi Agamemnon | D20: =IFERROR(__xludf.DUMMYFUNCTION("""COMPUTED_VALUE"""),"1128E2") -> 1128E2 | E20: =IFERROR(__xludf.DUMMYFUNCTION("""COMPUTED_VALUE"""),40555) -> 40555 | F20: =IFERROR(__xludf.DUMMYFUNCTION("""COMPUTED_VALUE"""),"3EME1") -> 3EME1 | G20: =IFERROR(__xludf.DUMMYFUNCTION("""COMPUTED_VALUE"""),"3ème") -> 3ème | H20: =IFERROR(__xludf.DUMMYFUNCTION("""COMPUTED_VALUE"""),"Lycée Français Jacques Prévert de Saly » Collège » 3ème » Générale") -> Lycée Français Jacques Prévert de Saly » Collège » 3ème » Générale | I20: =IFERROR(__xludf.DUMMYFUNCTION("""COMPUTED_VALUE"""),"LVA Anglais") -> LVA Anglais | J20: =IFERROR(__xludf.DUMMYFUNCTION("""COMPUTED_VALUE"""),"LVB Espagnol") -> LVB Espagnol | N20: =IFERROR(__xludf.DUMMYFUNCTION("""COMPUTED_VALUE"""),"Garçon") -> Garçon | P20: =IFERROR(__xludf.DUMMYFUNCTION("""COMPUTED_VALUE"""),"FRANCE") -> FRANCE | Q20: =IFERROR(__xludf.DUMMYFUNCTION("""COMPUTED_VALUE"""),"LIBERIA") -> LIBERIA | R20: =IFERROR(__xludf.DUMMYFUNCTION("""COMPUTED_VALUE"""),"albert.aubry@lfjpsaly.org") -> albert.aubry@lfjpsaly.org | T20: =IFERROR(__xludf.DUMMYFUNCTION("""COMPUTED_VALUE"""),"AUBRY Alexandre") -> AUBRY Alexandre | U20: =IFERROR(__xludf.DUMMYFUNCTION("""COMPUTED_VALUE"""),"AUBRY Soenie") -> AUBRY Soenie | V20: =IFERROR(__xludf.DUMMYFUNCTION("""COMPUTED_VALUE"""),"alexaubry.africa@gmail.com") -> alexaubry.africa@gmail.com | W20: =IFERROR(__xludf.DUMMYFUNCTION("""COMPUTED_VALUE"""),"asoenie@yahoo.com") -> asoenie@yahoo.com | X20: =IFERROR(__xludf.DUMMYFUNCTION("""COMPUTED_VALUE"""),"+221 77 333 22 22") -> +221 77 333 22 22 | Y20: =IFERROR(__xludf.DUMMYFUNCTION("""COMPUTED_VALUE"""),"+221 77 299 74 70") -> +221 77 299 74 70 | Z20: =IFERROR(__xludf.DUMMYFUNCTION("""COMPUTED_VALUE"""),"+221") -> +221 | AB20: =IFERROR(__xludf.DUMMYFUNCTION("""COMPUTED_VALUE"""),28575) -> 28575 | AC20: =IFERROR(__xludf.DUMMYFUNCTION("""COMPUTED_VALUE"""),30535) -> 30535 | AD20: =IFERROR(__xludf.DUMMYFUNCTION("""COMPUTED_VALUE"""),"PERE") -> PERE | AE20: =IFERROR(__xludf.DUMMYFUNCTION("""COMPUTED_VALUE"""),"MERE") -> MERE | AF20: =IFERROR(__xludf.DUMMYFUNCTION("""COMPUTED_VALUE"""),"FRANCE") -> FRANCE | AG20: =IFERROR(__xludf.DUMMYFUNCTION("""COMPUTED_VALUE"""),"LIBERIA") -> LIBERIA | AJ20: =IFERROR(__xludf.DUMMYFUNCTION("""COMPUTED_VALUE"""),"F1128") -> F1128 | AK20: =IFERROR(__xludf.DUMMYFUNCTION("""COMPUTED_VALUE"""),"Marié(e)") -> Marié(e) | AL20: =IFERROR(__xludf.DUMMYFUNCTION("""COMPUTED_VALUE"""),"Marié(e)") -> Marié(e) | AM20: =IFERROR(__xludf.DUMMYFUNCTION("""COMPUTED_VALUE"""),"F1128") -> F1128
